<?xml version="1.0" ?>
<robot name="robotdrive">
  <joint name="robotdrive__link_0_JOINT_0" type="continuous">
    <parent link="robotdrive__link_0"/>
    <child link="robotdrive__link_1"/>
    <origin xyz="1 1.2 0" rpy="1.57 0   0"/>
    <axis xyz="0 0 1"/>
    <limit lower="-1.79769e+308" upper="1.79769e+308" effort="-1.0" velocity="-1.0"/>
  </joint>
  <joint name="robotdrive__link_0_JOINT_1" type="continuous">
    <parent link="robotdrive__link_0"/>
    <child link="robotdrive__link_2"/>
    <origin xyz="1 -1.2  0" rpy="1.57 0   0"/>
    <axis xyz="0 0 1"/>
    <limit lower="-1.79769e+308" upper="1.79769e+308" effort="-1.0" velocity="-1.0"/>
  </joint>
  <joint name="robotdrive__link_0_JOINT_2" type="continuous">
    <parent link="robotdrive__link_0"/>
    <child link="robotdrive__link_5"/>
    <origin xyz="-1  1.2  0" rpy="1.57 0   0"/>
    <axis xyz="0 0 1"/>
    <limit lower="-1.79769e+308" upper="1.79769e+308" effort="-1.0" velocity="-1.0"/>
  </joint>
  <joint name="robotdrive__link_0_JOINT_3" type="continuous">
    <parent link="robotdrive__link_0"/>
    <child link="robotdrive__link_8"/>
    <origin xyz="-1 -1.2  0" rpy="1.57 0   0"/>
    <axis xyz="0 0 1"/>
    <limit lower="-1.79769e+308" upper="1.79769e+308" effort="-1.0" velocity="-1.0"/>
  </joint>
  <link name="robotdrive__link_0">
    <inertial>
      <mass value="1"/>
      <origin xyz="0 0 0" rpy="0 0 0"/>
      <inertia ixx="0.166667" ixy="0" ixz="0" iyy="0.166667" iyz="0" izz="0.166667"/>
    </inertial>
    <collision name="robotdrive__collision">
      <origin xyz="0 0 0" rpy="0 0 0"/>
      <geometry>
        <box size="1 1 1"/>
      </geometry>
    </collision>
    <visual name="robotdrive__visual">
      <origin xyz="0 0 0" rpy="0 0 0"/>
      <geometry>
        <box size="1 1 1"/>
      </geometry>
    </visual>
  </link>
  <link name="robotdrive__link_1">
    <inertial>
      <mass value="1"/>
      <origin xyz="0 0 0" rpy="0 0 0"/>
      <inertia ixx="0.145833" ixy="0" ixz="0" iyy="0.145833" iyz="0" izz="0.125"/>
    </inertial>
    <collision name="robotdrive__collision">
      <origin xyz="0 0 0" rpy="0 0 0"/>
      <geometry>
        <cylinder radius="0.5" length="1"/>
      </geometry>
    </collision>
    <visual name="robotdrive__visual">
      <origin xyz="0 0 0" rpy="0 0 0"/>
      <geometry>
        <cylinder radius="0.5" length="1"/>
      </geometry>
    </visual>
  </link>
  <link name="robotdrive__link_2">
    <inertial>
      <mass value="1"/>
      <origin xyz="0 0 0" rpy="0 0 0"/>
      <inertia ixx="0.145833" ixy="0" ixz="0" iyy="0.145833" iyz="0" izz="0.125"/>
    </inertial>
    <collision name="robotdrive__collision">
      <origin xyz="0 0 0" rpy="0 0 0"/>
      <geometry>
        <cylinder radius="0.5" length="1"/>
      </geometry>
    </collision>
    <visual name="robotdrive__visual">
      <origin xyz="0 0 0" rpy="0 0 0"/>
      <geometry>
        <cylinder radius="0.5" length="1"/>
      </geometry>
    </visual>
  </link>
  <link name="robotdrive__link_5">
    <inertial>
      <mass value="1"/>
      <origin xyz="0 0 0" rpy="0 0 0"/>
      <inertia ixx="0.145833" ixy="0" ixz="0" iyy="0.145833" iyz="0" izz="0.125"/>
    </inertial>
    <collision name="robotdrive__collision">
      <origin xyz="0 0 0" rpy="0 0 0"/>
      <geometry>
        <cylinder radius="0.5" length="1"/>
      </geometry>
    </collision>
    <visual name="robotdrive__visual">
      <origin xyz="0 0 0" rpy="0 0 0"/>
      <geometry>
        <cylinder radius="0.5" length="1"/>
      </geometry>
    </visual>
  </link>
  <link name="robotdrive__link_8">
    <inertial>
      <mass value="1"/>
      <origin xyz="0 0 0" rpy="0 0 0"/>
      <inertia ixx="0.145833" ixy="0" ixz="0" iyy="0.145833" iyz="0" izz="0.125"/>
    </inertial>
    <collision name="robotdrive__collision">
      <origin xyz="0 0 0" rpy="0 0 0"/>
      <geometry>
        <cylinder radius="0.5" length="1"/>
      </geometry>
    </collision>
    <visual name="robotdrive__visual">
      <origin xyz="0 0 0" rpy="0 0 0"/>
      <geometry>
        <cylinder radius="0.5" length="1"/>
      </geometry>
    </visual>
  </link>
  <gazebo>
    <plugin name="differential_drive_controller" filename="libgazebo_ros_diff_drive.so">

      <!-- Plugin update rate in Hz -->
      <updateRate>10.0</updateRate>

      <!-- Name of left joint, defaults to `left_joint` -->
      <leftJoint>robotdrive__link_0_JOINT_1</leftJoint>

      <!-- Name of right joint, defaults to `right_joint` -->
      <rightJoint>robotdrive__link_0_JOINT_0</rightJoint>

      <!-- The distance from the center of one wheel to the other, in meters, defaults to 0.34 m -->
      <wheelSeparation>2.4</wheelSeparation>

      <!-- Diameter of the wheels, in meters, defaults to 0.15 m -->
      <wheelDiameter>1.0</wheelDiameter>

      <!-- Wheel acceleration, in rad/s^2, defaults to 0.0 rad/s^2 -->
      <wheelAcceleration>1.0</wheelAcceleration>

      <!-- Maximum torque which the wheels can produce, in Nm, defaults to 5 Nm -->
      <wheelTorque>20</wheelTorque>

      <!-- Topic to receive geometry_msgs/Twist message commands, defaults to `cmd_vel` -->
      <commandTopic>cmd_vel</commandTopic>

      <!-- Topic to publish nav_msgs/Odometry messages, defaults to `odom` -->
      <odometryTopic>odom</odometryTopic>

      <!-- Odometry frame, defaults to `odom` -->
      <odometryFrame>odom</odometryFrame>

      <!-- Robot frame to calculate odometry from, defaults to `base_footprint` -->
      <robotBaseFrame>robotdrive__link_0</robotBaseFrame>

      <!-- Odometry source, 0 for ENCODER, 1 for WORLD, defaults to WORLD -->
      <odometrySource>1</odometrySource>

      <!-- Set to true to publish transforms for the wheel links, defaults to false -->
      <publishWheelTF>true</publishWheelTF>

      <!-- Set to true to publish transforms for the odometry, defaults to true -->
      <publishOdom>true</publishOdom>

      <!-- Set to true to publish sensor_msgs/JointState on /joint_states for the wheel joints, defaults to false -->
      <publishWheelJointState>true</publishWheelJointState>

      <!-- Set to true to swap right and left wheels, defaults to true -->
      <legacyMode>false</legacyMode>
    </plugin>
  </gazebo>

</robot>
